Workbook

Sheet 1-бет
K3: Форма ПУ - 74
D11: ГРАФИК
D12: по текущему содкржанию и оценка
D13: состояния иути и путевых устройств
C14: __________________________________ отделения___________________________________околотка
C15: ____________________________________участка на _____декабр______м-ц 2025 г.
C16: Контингент: расчетный_________чел._______________________________________чел./час
E17: минимальный_________________________"____________"
E18: фактический _________________________"_____________"
C19: Выполнение задания в чел/час._____________________________________________________________
C20: %выполнения наряд-задания_____________________________________________________________
D21: нормы выработки_________________________________________________________
C22: Аккордная сумма: по плану _________________________________________________________________
D23: к выплате ________________________________________________________________________
C25: Старщий нормировщик._____________________________________________________________________
H26: (подпись)
B32: Оплатить бригаде аккордную сумму в размере_____________________________________________________проц.
B33: Оплатить бригаде премию _____________________ _______________________________________ ___проц.
B34: Оплатить за руководство не освобожденному бригадиру пути _______________________________________ проц.
B35: Оплатить премию освобежденному бригадиру пути ____________________________________________проц.
B36: ___________________________________________________________________________________________
B37: ___________________________________________________________________________________________
B38: ___________________________________________________________________________________________
B39: __________________________________________________________________________________________
J43: Пч-16___________________
G45: 1

Sheet 2-3 бетлар
R1: околоток | S1: Бригада | T1: Шифр учета затрат | X1: производственная группа | Y1: профессия | Z1: категория
R2: Цех | T2: Синтетеик счет | U2: Аналитический учет
U3: суб счет | V3: статья расхода
A4: I. УЧЕТ РАБОЧЕГО ВРЕМЕНИ И ЗАРОБОТНОЙ ПЛАТЫ РАБОЧИХ | T4: 2 | V4: 8
R5: 7_8 | S5: 9 | T5: 14-15 | U5: 16 | V5: 17-19 | W5: 20 | X5: 21 | Y5: 22-24 | Z5: 25
A6: № | B6: Ф.И.О | C6: ЧИСЛА МЕСЯЦА | S6: Итого отработано часов | T6: Табельный номер | U6: Разряд рабочего | W6: Итого отработано часов. Приведен к первому разряду | X6: Вид оплаты
C7: 1 | D7: 2 | E7: 3 | F7: 4 | G7: 5 | H7: 6 | I7: 7 | J7: 8 | K7: 9 | L7: 10 | M7: 11 | N7: 12 | O7: 13 | P7: 14 | Q7: 15 | X7: 1 | Y7: 8
C9: 16 | D9: 17 | E9: 18 | F9: 19 | G9: 20 | H9: 21 | I9: 22 | J9: 23 | K9: 24 | L9: 25 | M9: 26 | N9: 27 | O9: 28 | P9: 29 | Q9: 30 | R9: 31 | T9: 26-29 | X9: Аккорд зараб | Y9: Сумма премии
X10: 34-38 | Y10: 34-38
A11: 1 | B11: Nazarov S | C11: 8 | D11: 8 | E11: 8 | F11: 8 | G11: 8 | K11: 8 | L11: 8 | M11: 8 | N11: 8 | Q11: 8 | S11: =SUM(C11:R12) -> 168 | T11: 216 | U11: 3
C12: 8 | D12: 8 | E12: 8 | F12: 8 | I12: 8 | J12: 8 | K12: 8 | L12: 8 | M12: 8 | P12: 8 | Q12: 8
A13: 2 | B13: Satturdiyev Q | C13: 8 | D13: 8 | E13: 8 | F13: 8 | G13: 8 | K13: 8 | L13: 8 | M13: 8 | N13: 8 | Q13: 8 | S13: =SUM(C13:R14) -> 168 | T13: 199 | U13: 3
C14: 8 | D14: 8 | E14: 8 | F14: 8 | I14: 8 | J14: 8 | K14: 8 | L14: 8 | M14: 8 | P14: 8 | Q14: 8
A15: 3 | B15: Adambayev A | C15: 8 | D15: 8 | E15: 8 | F15: 8 | G15: 8 | K15: 8 | L15: 8 | M15: 8 | N15: 8 | Q15: 8 | S15: =SUM(C15:R16) -> 168 | T15: 204 | U15: 3
C16: 8 | D16: 8 | E16: 8 | F16: 8 | I16: 8 | J16: 8 | K16: 8 | L16: 8 | M16: 8 | P16: 8 | Q16: 8
A17: 4 | B17: Mardinov E | C17: 8 | D17: 8 | E17: 8 | F17: 8 | G17: 8 | K17: 8 | L17: 8 | M17: 8 | N17: 8 | Q17: 8 | S17: =SUM(C17:R18) -> 168 | T17: 202 | U17: 3
C18: 8 | D18: 8 | E18: 8 | F18: 8 | I18: 8 | J18: 8 | K18: 8 | L18: 8 | M18: 8 | P18: 8 | Q18: 8
A19: 5 | B19: Orazbekov J | C19: 8 | D19: 8 | E19: 8 | F19: 8 | G19: 8 | K19: 8 | L19: 8 | M19: 8 | N19: 8 | Q19: 8 | S19: =SUM(C19:R20) -> 168 | T19: 198 | U19: 3
C20: 8 | D20: 8 | E20: 8 | F20: 8 | I20: 8 | J20: 8 | K20: 8 | L20: 8 | M20: 8 | P20: 8 | Q20: 8
A21: 6 | B21: G'aybullayev A | C21: 8 | D21: 8 | E21: 8 | F21: 8 | G21: 8 | K21: 8 | L21: 8 | M21: 8 | N21: 8 | Q21: 8 | S21: =SUM(C21:R22) -> 80 | T21: 435 | U21: 3
A23: 7 | B23: Murodov U | C23: 8 | D23: 8 | E23: 8 | F23: 8 | G23: 8 | K23: 8 | L23: 8 | M23: 8 | N23: 8 | Q23: 8 | S23: =SUM(C23:R24) -> 168 | T23: 013 | U23: 3
C24: 8 | D24: 8 | E24: 8 | F24: 8 | I24: 8 | J24: 8 | K24: 8 | L24: 8 | M24: 8 | P24: 8 | Q24: 8
A25: 8 | B25: Jalolov I | C25: b | D25: b | E25: b | F25: b | G25: b | K25: 8 | L25: 8 | M25: 8 | N25: 8 | Q25: 8 | S25: =SUM(C25:R26) -> 128 | T25: 366 | U25: 3
C26: 8 | D26: 8 | E26: 8 | F26: 8 | I26: 8 | J26: 8 | K26: 8 | L26: 8 | M26: 8 | P26: 8 | Q26: 8
A27: 9 | B27: Toshpo'latov O | C27: 8 | D27: 8 | E27: 8 | F27: 8 | G27: 8 | K27: 8 | L27: 8 | M27: 8 | N27: 8 | Q27: 8 | S27: =SUM(C27:R28) -> 168 | T27: 219 | U27: 3
C28: 8 | D28: 8 | E28: 8 | F28: 8 | I28: 8 | J28: 8 | K28: 8 | L28: 8 | M28: 8 | P28: 8 | Q28: 8
A29: 10 | S29: =SUM(C29:R30) -> 0
A31: 11 | S31: =SUM(C31:R32) -> 0
A33: 12 | S33: =SUM(C33:R34) -> 0
A35: 13 | S35: =SUM(C35:R36) -> 0
A37: 14 | S37: =SUM(C37:R38) -> 0
A39: 15 | S39: =SUM(C39:R40) -> 0
C41: =SUM(C23,C25,C27,C29,C31,C33,C35,C37,C39,C21,C19,C17,C15,C13,C11) -> 64 | D41: =SUM(D23,D25,D27,D29,D31,D33,D35,D37,D39,D21,D19,D17,D15,D13,D11) -> 64 | E41: =SUM(E23,E25,E27,E29,E31,E33,E35,E37,E39,E21,E19,E17,E15,E13,E11) -> 64 | F41: =SUM(F23,F25,F27,F29,F31,F33,F35,F37,F39,F21,F19,F17,F15,F13,F11) -> 64 | G41: =SUM(G23,G25,G27,G29,G31,G33,G35,G37,G39,G21,G19,G17,G15,G13,G11) -> 64 | H41: =SUM(H23,H25,H27,H29,H31,H33,H35,H37,H39,H21,H19,H17,H15,H13,H11) -> 0 | I41: =SUM(I23,I25,I27,I29,I31,I33,I35,I37,I39,I21,I19,I17,I15,I13,I11) -> 0 | J41: =SUM(J23,J25,J27,J29,J31,J33,J35,J37,J39,J21,J19,J17,J15,J13,J11) -> 0 | ... R41: =SUM(R23,R25,R27,R29,R31,R33,R35,R37,R39,R21,R19,R17,R15,R13,R11) -> 0 | S41: =SUM(C41:R41) -> 680
C42: =SUM(C24,C26,C28,C30,C32,C34,C36,C38,C40,C22,C20,C18,C16,C14,C12) -> 64 | D42: =SUM(D24,D26,D28,D30,D32,D34,D36,D38,D40,D22,D20,D18,D16,D14,D12) -> 64 | E42: =SUM(E24,E26,E28,E30,E32,E34,E36,E38,E40,E22,E20,E18,E16,E14,E12) -> 64 | F42: =SUM(F24,F26,F28,F30,F32,F34,F36,F38,F40,F22,F20,F18,F16,F14,F12) -> 64 | G42: =SUM(G24,G26,G28,G30,G32,G34,G36,G38,G40,G22,G20,G18,G16,G14,G12) -> 0 | H42: =SUM(H24,H26,H28,H30,H32,H34,H36,H38,H40,H22,H20,H18,H16,H14,H12) -> 0 | I42: =SUM(I24,I26,I28,I30,I32,I34,I36,I38,I40,I22,I20,I18,I16,I14,I12) -> 64 | J42: =SUM(J24,J26,J28,J30,J32,J34,J36,J38,J40,J22,J20,J18,J16,J14,J12) -> 64 | ... R42: =SUM(R24,R26,R28,R30,R32,R34,R36,R38,R40,R22,R20,R18,R16,R14,R12) -> 0 | S42: =SUM(C42:R42) -> 704
S43: =SUM(S11:S40) -> 1384
B44: Аккордный заработок за 1 час, приведенный к 1-разряду _______________________________ | Q44: Итого:
B45: Процент премии к выплате __________________________ | S45: Расчет составил ______________________________________
B46: ПДБ _________________________ | X46: (подпись)
B47: (подпись) | S47: Нормировщик __________________
B48: ПД __________________________ | Y48: (подпись)
...

Sheet 4-5 бетлар
C1: II. ПЛАН И ВЫПОЛНЕНИЕ РАБОТ | K1: Неотложные работы | T1: Плани и выполнение задание | AA1: Итого часов
A2: № п-п | B2: Место работы(км, пикет, звено, № станционного пути № стрелки и.т.д. ) | C2: Наимование (с указанием рпименяемых механизмов) | D2: Единица измерения | F2: Норма времени на измеритель в чел/час &норм | H2: норма выработки | I2: Задание | K2: Числа месяца | AA2: Фактически отработанных | AB2: Нормированных | AC2: Обьем выполненных работ | AD2: №№ статей расхода
I3: Количество работ | J3: Нормированное время на заданию работу в ч-час
K4: 1 | L4: 2 | M4: 3 | N4: 4 | O4: 5 | P4: 6 | Q4: 7 | R4: 8 | S4: 9 | T4: 10 | U4: 11 | V4: 12 | W4: 13 | X4: 14 | Y4: 15
A5: 1 | C5: Исправление просадок к перекосов пути на щебеночном балласте подбивкой шпал ЭШП-9 | D5: 10 | E5: шпал | F5: § 1 | G5: 1.55 | H5: 4 | I5: =+J5*D5/G5 -> 0 | AA5: =SUM(K5:Z5) -> 0 | AB5: =SUM(K5:Z5) -> 0 | AC5: =SUM(K6:Z6) -> 0
K6: =+K5/$G5*$D5 -> 0 | L6: =+L5/$G5*$D5 -> 0 | M6: =+M5/$G5*$D5 -> 0 | N6: =+N5/$G5*$D5 -> 0 | O6: =+O5/$G5*$D5 -> 0 | P6: =+P5/$G5*$D5 -> 0 | Q6: =+Q5/$G5*$D5 -> 0 | R6: =+R5/$G5*$D5 -> 0 | ... Z6: =+Z5/$G5*$D5 -> 0
A7: 2 | B7: 4118 km pk 1 dan 4128 km pk 10 | C7: Выправка пути по уровню на величину до 10мм укладкой или заменой регулировочных прокладок | D7: 10 | E7: конц шпал | F7: § 19 | G7: 0.948 | H7: 4 | I7: =+J7*D7/G7 -> 4113.9241 | J7: 390 | K7: 36 | L7: 36 | M7: 36 | N7: 36 | O7: 36 | S7: 44 | T7: 28 | U7: 44 | V7: 44 | Y7: 44 | AA7: =SUM(K7:Z7) -> 384 | AB7: =SUM(K7:Z7) -> 384 | AC7: =SUM(K8:Z8) -> 4050.6329
K8: =+K7/$G7*$D7 -> 379.74684 | L8: =+L7/$G7*$D7 -> 379.74684 | M8: =+M7/$G7*$D7 -> 379.74684 | N8: =+N7/$G7*$D7 -> 379.74684 | O8: =+O7/$G7*$D7 -> 379.74684 | P8: =+P7/$G7*$D7 -> 0 | Q8: =+Q7/$G7*$D7 -> 0 | R8: =+R7/$G7*$D7 -> 0 | ... Z8: =+Z7/$G7*$D7 -> 0
A9: 3 | B9: 4118 km pk 1 dan 4128 km pk 10 | C9: Поправка подрельсовых (амортизационных) прокладок при раздельном скреплении | D9: 10 | E9: конц /шпал | F9: § 20 | G9: 0.558 | H9: 4 | I9: =+J9*D9/G9 -> 1971.3262 | J9: 110 | K9: 10 | L9: 10 | M9: 10 | N9: 10 | O9: 10 | S9: 10 | T9: 10 | U9: 10 | V9: 10 | Y9: 10 | AA9: =SUM(K9:Z9) -> 100 | AB9: =SUM(K9:Z9) -> 100 | AC9: =SUM(K10:Z10) -> 1792.1147
K10: =+K9/$G9*$D9 -> 179.21147 | L10: =+L9/$G9*$D9 -> 179.21147 | M10: =+M9/$G9*$D9 -> 179.21147 | N10: =+N9/$G9*$D9 -> 179.21147 | O10: =+O9/$G9*$D9 -> 179.21147 | P10: =+P9/$G9*$D9 -> 0 | Q10: =+Q9/$G9*$D9 -> 0 | R10: =+R9/$G9*$D9 -> 0 | ... Z10: =+Z9/$G9*$D9 -> 0
A11: 4 | C11: Сверление больтовых отверстий в рельсах электрическами рельсосверильными станками | D11: 10 | E11: релс свер | F11: § 48 | G11: 2.25 | H11: 3 | I11: =+J11*D11/G11 -> 0 | AA11: =SUM(K11:Z11) -> 0 | AB11: =SUM(K11:Z11) -> 0 | AC11: =SUM(K12:Z12) -> 0
K12: =+K11/$G11*$D11 -> 0 | L12: =+L11/$G11*$D11 -> 0 | M12: =+M11/$G11*$D11 -> 0 | N12: =+N11/$G11*$D11 -> 0 | O12: =+O11/$G11*$D11 -> 0 | P12: =+P11/$G11*$D11 -> 0 | Q12: =+Q11/$G11*$D11 -> 0 | R12: =+R11/$G11*$D11 -> 0 | ... Z12: =+Z11/$G11*$D11 -> 0
A13: 5 | C13: Резка рельсов электрическим рельсорезным станком РМ-3 | D13: 1 | E13: рельс | F13: § 51 | G13: 0.795 | H13: 3 | I13: =+J13*D13/G13 -> 0 | AA13: =SUM(K13:Z13) -> 0 | AB13: =SUM(K13:Z13) -> 0 | AC13: =SUM(K14:Z14) -> 0
K14: =+K13/$G13*$D13 -> 0 | L14: =+L13/$G13*$D13 -> 0 | M14: =+M13/$G13*$D13 -> 0 | N14: =+N13/$G13*$D13 -> 0 | O14: =+O13/$G13*$D13 -> 0 | P14: =+P13/$G13*$D13 -> 0 | Q14: =+Q13/$G13*$D13 -> 0 | R14: =+R13/$G13*$D13 -> 0 | ... Z14: =+Z13/$G13*$D13 -> 0
A15: 6 | C15: Очистка централизованных стрелочных переводов от грязи и мусора | D15: 1 | E15: стрл/пер | F15: § 58 | G15: 2.42 | H15: 3 | I15: =+J15*D15/G15 -> 0 | AA15: =SUM(K15:Z15) -> 0 | AB15: =SUM(K15:Z15) -> 0 | AC15: =SUM(K16:Z16) -> 0
K16: =+K15/$G15*$D15 -> 0 | L16: =+L15/$G15*$D15 -> 0 | M16: =+M15/$G15*$D15 -> 0 | N16: =+N15/$G15*$D15 -> 0 | O16: =+O15/$G15*$D15 -> 0 | P16: =+P15/$G15*$D15 -> 0 | Q16: =+Q15/$G15*$D15 -> 0 | R16: =+R15/$G15*$D15 -> 0 | ... Z16: =+Z15/$G15*$D15 -> 0
A17: 7 | C17: Регулировка ширины колен на стрелочном переводе с рпименением стяжного прибора | D17: 10 | E17: конц/брус | F17: § 60 | G17: 1.57 | H17: 5 | I17: =+J17*D17/G17 -> 0 | AA17: =SUM(K17:Z17) -> 0 | AB17: =SUM(K17:Z17) -> 0 | AC17: =SUM(K18:Z18) -> 0
K18: =+K17/$G17*$D17 -> 0 | L18: =+L17/$G17*$D17 -> 0 | M18: =+M17/$G17*$D17 -> 0 | N18: =+N17/$G17*$D17 -> 0 | O18: =+O17/$G17*$D17 -> 0 | P18: =+P17/$G17*$D17 -> 0 | Q18: =+Q17/$G17*$D17 -> 0 | R18: =+R17/$G17*$D17 -> 0 | ... Z18: =+Z17/$G17*$D17 -> 0
A19: 8 | C19: Подтягивание гаек клеммных и закладных болтов торцовыми ключами | D19: 100 | E19: гаек | F19: § 41 | G19: 0.421 | H19: 4 | I19: =+J19*D19/G19 -> 0 | AA19: =SUM(K19:Z19) -> 0 | AB19: =SUM(K19:Z19) -> 0 | AC19: =SUM(K20:Z20) -> 0
K20: =+K19/$G19*$D19 -> 0 | L20: =+L19/$G19*$D19 -> 0 | M20: =+M19/$G19*$D19 -> 0 | N20: =+N19/$G19*$D19 -> 0 | O20: =+O19/$G19*$D19 -> 0 | P20: =+P19/$G19*$D19 -> 0 | Q20: =+Q19/$G19*$D19 -> 0 | R20: =+R19/$G19*$D19 -> 0 | ... Z20: =+Z19/$G19*$D19 -> 0
A21: 9 | B21: 4118 km pk 1 dan 4128 km pk 10 | C21: рыхтовка пути | D21: 100 | E21: дорог | F21: § 39 1990г. | G21: 7.59 | H21: 3 | I21: =+J21*D21/G21 -> 790.51383 | J21: 60 | K21: 5 | L21: 5 | M21: 5 | N21: 5 | O21: 5 | S21: 5 | T21: 5 | U21: 5 | V21: 5 | Y21: 5 | AA21: =SUM(K21:Z21) -> 50 | AB21: =SUM(K21:Z21) -> 50 | AC21: =SUM(K22:Z22) -> 658.76153
K22: =+K21/$G21*$D21 -> 65.876153 | L22: =+L21/$G21*$D21 -> 65.876153 | M22: =+M21/$G21*$D21 -> 65.876153 | N22: =+N21/$G21*$D21 -> 65.876153 | O22: =+O21/$G21*$D21 -> 65.876153 | P22: =+P21/$G21*$D21 -> 0 | Q22: =+Q21/$G21*$D21 -> 0 | R22: =+R21/$G21*$D21 -> 0 | ... Z22: =+Z21/$G21*$D21 -> 0
A23: 10 | C23: Смена изолирующих прокладок в изолирующем стыке | D23: 1 | E23: стик | F23: § 38 | G23: 2.05 | H23: 4 | I23: =+J23*D23/G23 -> 0 | AA23: =SUM(K23:Z23) -> 0 | AB23: =SUM(K23:Z23) -> 0 | AC23: =SUM(K24:Z24) -> 0
K24: =+K23/$G23*$D23 -> 0 | L24: =+L23/$G23*$D23 -> 0 | M24: =+M23/$G23*$D23 -> 0 | N24: =+N23/$G23*$D23 -> 0 | O24: =+O23/$G23*$D23 -> 0 | P24: =+P23/$G23*$D23 -> 0 | Q24: =+Q23/$G23*$D23 -> 0 | R24: =+R23/$G23*$D23 -> 0 | ... Z24: =+Z23/$G23*$D23 -> 0
A25: 11 | B25: 4118 km pk 1 dan 4128 km pk 10 | C25: Регулировка ширины рельсовой колеи при раздельном скреплении с применением стяжного прибора | D25: 10 | E25: конц/шпал | F25: § 18 | G25: 0.501 | H25: 4 | I25: =+J25*D25/G25 -> 1197.6048 | J25: 60 | K25: 5 | L25: 5 | M25: 5 | N25: 5 | O25: 5 | S25: 5 | T25: 5 | U25: 5 | V25: 5 | Y25: 5 | AA25: =SUM(K25:Z25) -> 50 | AB25: =SUM(K25:Z25) -> 50 | AC25: =SUM(K26:Z26) -> 998.00399
K26: =+K25/$G25*$D25 -> 99.800399 | L26: =+L25/$G25*$D25 -> 99.800399 | M26: =+M25/$G25*$D25 -> 99.800399 | N26: =+N25/$G25*$D25 -> 99.800399 | O26: =+O25/$G25*$D25 -> 99.800399 | P26: =+P25/$G25*$D25 -> 0 | Q26: =+Q25/$G25*$D25 -> 0 | R26: =+R25/$G25*$D25 -> 0 | ... Z26: =+Z25/$G25*$D25 -> 0
A27: 12 | C27: Смена железобетонных шпал (одиночная) на щебеночном баласте при раздельном скреплении КБ и скреплении PANDROL FAST CLIP | D27: 1 | E27: шпал | F27: § 11 | G27: 1.83 | H27: 3.6 | I27: =+J27*D27/G27 -> 0 | AA27: =SUM(K27:Z27) -> 0 | AB27: =SUM(K27:Z27) -> 0 | AC27: =SUM(K28:Z28) -> 0
K28: =+K27/$G27*$D27 -> 0 | L28: =+L27/$G27*$D27 -> 0 | M28: =+M27/$G27*$D27 -> 0 | N28: =+N27/$G27*$D27 -> 0 | O28: =+O27/$G27*$D27 -> 0 | P28: =+P27/$G27*$D27 -> 0 | Q28: =+Q27/$G27*$D27 -> 0 | R28: =+R27/$G27*$D27 -> 0 | ... Z28: =+Z27/$G27*$D27 -> 0
A29: 13 | C29: Выправка стрелочного перевода подбивкой брусьев электрошполопобойками ЭШП-9 | D29: 10 | E29: м/брус | F29: § 59 | G29: 1.3 | H29: 5 | I29: =+J29*D29/G29 -> 0 | AA29: =SUM(K29:Z29) -> 0 | AB29: =SUM(K29:Z29) -> 0 | AC29: =SUM(K30:Z30) -> 0
K30: =+K29/$G29*$D29 -> 0 | L30: =+L29/$G29*$D29 -> 0 | M30: =+M29/$G29*$D29 -> 0 | N30: =+N29/$G29*$D29 -> 0 | O30: =+O29/$G29*$D29 -> 0 | P30: =+P29/$G29*$D29 -> 0 | Q30: =+Q29/$G29*$D29 -> 0 | R30: =+R29/$G29*$D29 -> 0 | ... Z30: =+Z29/$G29*$D29 -> 0
A31: 14 | B31: 4124 km pk 1, 4122 km pk 7, 4123 km pk 7, 4128 km pk 10, | C31: Смена рельсов типов Р65 и Р50 при раздельном скреплении (одиночная) | D31: 1 | E31: рельс | F31: § 21 | G31: 2 | H31: 3.6 | I31: =+J31*D31/G31 -> 8 | J31: 16 | U31: 16 | AA31: =SUM(K31:Z31) -> 16 | AB31: =SUM(K31:Z31) -> 16 | AC31: =SUM(K32:Z32) -> 8
K32: =+K31/$G31*$D31 -> 0 | L32: =+L31/$G31*$D31 -> 0 | M32: =+M31/$G31*$D31 -> 0 | N32: =+N31/$G31*$D31 -> 0 | O32: =+O31/$G31*$D31 -> 0 | P32: =+P31/$G31*$D31 -> 0 | Q32: =+Q31/$G31*$D31 -> 0 | R32: =+R31/$G31*$D31 -> 0 | ... Z32: =+Z31/$G31*$D31 -> 0
A33: 15 | B33: 4118 km - 4136 km | C33: Обход пути | H33: 3 | J33: 80 | K33: 8 | L33: 8 | M33: 8 | N33: 8 | O33: 8 | S33: 8 | T33: 8 | U33: 8 | V33: 8 | Y33: 8 | AA33: =SUM(K33:Z33) -> 80 | AB33: =SUM(K33:Z33) -> 80
A34: 16 | C34: Смена рельсов типов Р65 и Р50 при смешанном костыльном скреплении | D34: 1 | E34: рельс | F34: § 22 | G34: 3.69 | H34: 2.8 | I34: =+J34*D34/G34 -> 0 | AA34: =SUM(K34:Z34) -> 0 | AB34: =SUM(K34:Z34) -> 0 | AC34: =SUM(K35:Z35) -> 0
K35: =+K34/$G34*$D34 -> 0 | L35: =+L34/$G34*$D34 -> 0 | M35: =+M34/$G34*$D34 -> 0 | N35: =+N34/$G34*$D34 -> 0 | O35: =+O34/$G34*$D34 -> 0 | P35: =+P34/$G34*$D34 -> 0 | Q35: =+Q34/$G34*$D34 -> 0 | R35: =+R34/$G34*$D34 -> 0 | ... Z35: =+Z34/$G34*$D34 -> 0
C36: жами | I36: =SUM(I5:I35) -> 8081.3688 | J36: =SUM(J5:J35) -> 716 | K36: =+K5+K7+K9+K11+K13+K15+K17+K19+K21+K23+K25+K27+K29+K31+K34+K33 -> 64 | L36: =+L5+L7+L9+L11+L13+L15+L17+L19+L21+L23+L25+L27+L29+L31+L34+L33 -> 64 | M36: =+M5+M7+M9+M11+M13+M15+M17+M19+M21+M23+M25+M27+M29+M31+M34+M33 -> 64 | N36: =+N5+N7+N9+N11+N13+N15+N17+N19+N21+N23+N25+N27+N29+N31+N34+N33 -> 64 | O36: =+O5+O7+O9+O11+O13+O15+O17+O19+O21+O23+O25+O27+O29+O31+O34+O33 -> 64 | P36: =+P5+P7+P9+P11+P13+P15+P17+P19+P21+P23+P25+P27+P29+P31+P34+P33 -> 0 | Q36: =+Q5+Q7+Q9+Q11+Q13+Q15+Q17+Q19+Q21+Q23+Q25+Q27+Q29+Q31+Q34+Q33 -> 0 | R36: =+R5+R7+R9+R11+R13+R15+R17+R19+R21+R23+R25+R27+R29+R31+R34+R33 -> 0 | ... Z36: =+Z5+Z7+Z9+Z11+Z13+Z15+Z17+Z19+Z21+Z23+Z25+Z27+Z29+Z31+Z34+Z33 -> 0 | AA36: =SUM(K36:Z36) -> 680 | AB36: =SUM(AB5:AB35) -> 680 | AC36: =SUM(AC5:AC35) -> 7507.5131
C38: проверит | K38: =+'2-3 бетлар'!C41 -> 64 | L38: =+'2-3 бетлар'!D41 -> 64 | M38: =+'2-3 бетлар'!E41 -> 64 | N38: =+'2-3 бетлар'!F41 -> 64 | O38: =+'2-3 бетлар'!G41 -> 64 | P38: =+'2-3 бетлар'!H41 -> 0 | Q38: =+'2-3 бетлар'!I41 -> 0 | R38: =+'2-3 бетлар'!J41 -> 0 | ... AA38: =+'2-3 бетлар'!S41 -> 680
B40: Задание выдал ПД___________________________________________ | K40: Принял к исполнению ПД_____________________Работы выполнени ПДБ________________________________
D41: (подпись) | R41: (подпись) | AB41: (подпись)
A42: Примечани: 1.Попунктирной линии проводится сплошная черта, определяющая время работ по плану. | K42: Качество выполненных работ
...

Sheet 6-7 бетлар
C1: II. ПЛАН И ВЫПОЛНЕНИЕ РАБОТ | K1: Неотложные работы | T1: Плани и выполнение задание | AA1: Итого часов
A2: № п-п | B2: Место работы(км, пикет, звено, № станционного пути № стрелки и.т.д. ) | C2: Наимование (с указанием рпименяемых механизмов) | D2: Единица измерения | F2: Норма времени на измеритель в чел/час &норм | H2: норма выработки | I2: Задание | K2: Числа месяца | AA2: Фактически отработанных | AB2: Нормированных | AC2: Обьем выполненных работ | AD2: №№ статей расхода
I3: Количество работ | J3: Нормированное время на заданию работу в ч-час
K4: 16 | L4: 17 | M4: 18 | N4: 19 | O4: 20 | P4: 21 | Q4: 22 | R4: 23 | S4: 24 | T4: 25 | U4: 26 | V4: 27 | W4: 28 | X4: 29 | Y4: 30 | Z4: 31
A5: 1 | C5: Исправление просадок к перекосов пути на щебеночном балласте подбивкой шпал ЭШП-9 | D5: 10 | E5: шпал | F5: § 1 | G5: 1.55 | H5: 4 | I5: =+J5*D5/G5 -> 0 | AA5: =SUM(K5:Z5) -> 0 | AB5: =SUM(K5:Z5) -> 0 | AC5: =SUM(K6:Z6) -> 0
K6: =+K5/$G5*$D5 -> 0 | L6: =+L5/$G5*$D5 -> 0 | M6: =+M5/$G5*$D5 -> 0 | N6: =+N5/$G5*$D5 -> 0 | O6: =+O5/$G5*$D5 -> 0 | P6: =+P5/$G5*$D5 -> 0 | Q6: =+Q5/$G5*$D5 -> 0 | R6: =+R5/$G5*$D5 -> 0 | ... Z6: =+Z5/$G5*$D5 -> 0
A7: 2 | B7: 4118 km pk 1 dan 4128 km pk 10 | C7: Выправка пути по уровню на величину до 10мм укладкой или заменой регулировочных прокладок | D7: 10 | E7: конц шпал | F7: § 19 | G7: 0.948 | H7: 4 | I7: =+J7*D7/G7 -> 3270.0422 | J7: 310 | K7: 28 | L7: 28 | M7: 28 | N7: 28 | Q7: 28 | R7: 28 | S7: 28 | T7: 28 | U7: 28 | X7: 28 | Y7: 28 | AA7: =SUM(K7:Z7) -> 308 | AB7: =SUM(K7:Z7) -> 308 | AC7: =SUM(K8:Z8) -> 3248.9451
K8: =+K7/$G7*$D7 -> 295.35865 | L8: =+L7/$G7*$D7 -> 295.35865 | M8: =+M7/$G7*$D7 -> 295.35865 | N8: =+N7/$G7*$D7 -> 295.35865 | O8: =+O7/$G7*$D7 -> 0 | P8: =+P7/$G7*$D7 -> 0 | Q8: =+Q7/$G7*$D7 -> 295.35865 | R8: =+R7/$G7*$D7 -> 295.35865 | ... Z8: =+Z7/$G7*$D7 -> 0
A9: 3 | B9: 4118 km pk 1 dan 4128 km pk 10 | C9: Поправка подрельсовых (амортизационных) прокладок при раздельном скреплении | D9: 10 | E9: конц /шпал | F9: § 20 | G9: 0.558 | H9: 4 | I9: =+J9*D9/G9 -> 2508.9606 | J9: 140 | K9: 12 | L9: 12 | M9: 12 | N9: 12 | Q9: 12 | R9: 12 | S9: 12 | T9: 12 | U9: 12 | X9: 12 | Y9: 12 | AA9: =SUM(K9:Z9) -> 132 | AB9: =SUM(K9:Z9) -> 132 | AC9: =SUM(K10:Z10) -> 2365.5914
K10: =+K9/$G9*$D9 -> 215.05376 | L10: =+L9/$G9*$D9 -> 215.05376 | M10: =+M9/$G9*$D9 -> 215.05376 | N10: =+N9/$G9*$D9 -> 215.05376 | O10: =+O9/$G9*$D9 -> 0 | P10: =+P9/$G9*$D9 -> 0 | Q10: =+Q9/$G9*$D9 -> 215.05376 | R10: =+R9/$G9*$D9 -> 215.05376 | ... Z10: =+Z9/$G9*$D9 -> 0
A11: 4 | C11: Сверление больтовых отверстий в рельсах электрическами рельсосверильными станками | D11: 10 | E11: релс свер | F11: § 48 | G11: 2.25 | H11: 3 | I11: =+J11*D11/G11 -> 0 | AA11: =SUM(K11:Z11) -> 0 | AB11: =SUM(K11:Z11) -> 0 | AC11: =SUM(K12:Z12) -> 0
K12: =+K11/$G11*$D11 -> 0 | L12: =+L11/$G11*$D11 -> 0 | M12: =+M11/$G11*$D11 -> 0 | N12: =+N11/$G11*$D11 -> 0 | O12: =+O11/$G11*$D11 -> 0 | P12: =+P11/$G11*$D11 -> 0 | Q12: =+Q11/$G11*$D11 -> 0 | R12: =+R11/$G11*$D11 -> 0 | ... Z12: =+Z11/$G11*$D11 -> 0
A13: 5 | C13: Резка рельсов электрическим рельсорезным станком РМ-3 | D13: 1 | E13: рельс | F13: § 51 | G13: 0.795 | H13: 3 | I13: =+J13*D13/G13 -> 0 | AA13: =SUM(K13:Z13) -> 0 | AB13: =SUM(K13:Z13) -> 0 | AC13: =SUM(K14:Z14) -> 0
K14: =+K13/$G13*$D13 -> 0 | L14: =+L13/$G13*$D13 -> 0 | M14: =+M13/$G13*$D13 -> 0 | N14: =+N13/$G13*$D13 -> 0 | O14: =+O13/$G13*$D13 -> 0 | P14: =+P13/$G13*$D13 -> 0 | Q14: =+Q13/$G13*$D13 -> 0 | R14: =+R13/$G13*$D13 -> 0 | ... Z14: =+Z13/$G13*$D13 -> 0
A15: 6 | C15: Очистка централизованных стрелочных переводов от грязи и мусора | D15: 1 | E15: стрл/пер | F15: § 58 | G15: 2.42 | H15: 3 | I15: =+J15*D15/G15 -> 0 | AA15: =SUM(K15:Z15) -> 0 | AB15: =SUM(K15:Z15) -> 0 | AC15: =SUM(K16:Z16) -> 0
K16: =+K15/$G15*$D15 -> 0 | L16: =+L15/$G15*$D15 -> 0 | M16: =+M15/$G15*$D15 -> 0 | N16: =+N15/$G15*$D15 -> 0 | O16: =+O15/$G15*$D15 -> 0 | P16: =+P15/$G15*$D15 -> 0 | Q16: =+Q15/$G15*$D15 -> 0 | R16: =+R15/$G15*$D15 -> 0 | ... Z16: =+Z15/$G15*$D15 -> 0
A17: 7 | C17: Регулировка ширины колен на стрелочном переводе с рпименением стяжного прибора | D17: 10 | E17: конц/брус | F17: § 60 | G17: 1.57 | H17: 5 | I17: =+J17*D17/G17 -> 0 | AA17: =SUM(K17:Z17) -> 0 | AB17: =SUM(K17:Z17) -> 0 | AC17: =SUM(K18:Z18) -> 0
K18: =+K17/$G17*$D17 -> 0 | L18: =+L17/$G17*$D17 -> 0 | M18: =+M17/$G17*$D17 -> 0 | N18: =+N17/$G17*$D17 -> 0 | O18: =+O17/$G17*$D17 -> 0 | P18: =+P17/$G17*$D17 -> 0 | Q18: =+Q17/$G17*$D17 -> 0 | R18: =+R17/$G17*$D17 -> 0 | ... Z18: =+Z17/$G17*$D17 -> 0
A19: 8 | C19: Подтягивание гаек клеммных и закладных болтов торцовыми ключами | D19: 100 | E19: гаек | F19: § 41 | G19: 0.421 | H19: 4 | I19: =+J19*D19/G19 -> 0 | AA19: =SUM(K19:Z19) -> 0 | AB19: =SUM(K19:Z19) -> 0 | AC19: =SUM(K20:Z20) -> 0
K20: =+K19/$G19*$D19 -> 0 | L20: =+L19/$G19*$D19 -> 0 | M20: =+M19/$G19*$D19 -> 0 | N20: =+N19/$G19*$D19 -> 0 | O20: =+O19/$G19*$D19 -> 0 | P20: =+P19/$G19*$D19 -> 0 | Q20: =+Q19/$G19*$D19 -> 0 | R20: =+R19/$G19*$D19 -> 0 | ... Z20: =+Z19/$G19*$D19 -> 0
A21: 9 | B21: 4118 km pk 1 dan 4128 km pk 10 | C21: рыхтовка пути | D21: 100 | E21: дорог | F21: § 39 1990г. | G21: 7.59 | H21: 3 | I21: =+J21*D21/G21 -> 1185.7708 | J21: 90 | K21: 8 | L21: 8 | M21: 8 | N21: 8 | Q21: 8 | R21: 8 | S21: 8 | T21: 8 | U21: 8 | X21: 8 | Y21: 8 | AA21: =SUM(K21:Z21) -> 88 | AB21: =SUM(K21:Z21) -> 88 | AC21: =SUM(K22:Z22) -> 1159.4203
K22: =+K21/$G21*$D21 -> 105.40184 | L22: =+L21/$G21*$D21 -> 105.40184 | M22: =+M21/$G21*$D21 -> 105.40184 | N22: =+N21/$G21*$D21 -> 105.40184 | O22: =+O21/$G21*$D21 -> 0 | P22: =+P21/$G21*$D21 -> 0 | Q22: =+Q21/$G21*$D21 -> 105.40184 | R22: =+R21/$G21*$D21 -> 105.40184 | ... Z22: =+Z21/$G21*$D21 -> 0
A23: 10 | C23: Смена изолирующих прокладок в изолирующем стыке | D23: 1 | E23: стик | F23: § 38 | G23: 2.05 | H23: 4 | I23: =+J23*D23/G23 -> 0 | AA23: =SUM(K23:Z23) -> 0 | AB23: =SUM(K23:Z23) -> 0 | AC23: =SUM(K24:Z24) -> 0
K24: =+K23/$G23*$D23 -> 0 | L24: =+L23/$G23*$D23 -> 0 | M24: =+M23/$G23*$D23 -> 0 | N24: =+N23/$G23*$D23 -> 0 | O24: =+O23/$G23*$D23 -> 0 | P24: =+P23/$G23*$D23 -> 0 | Q24: =+Q23/$G23*$D23 -> 0 | R24: =+R23/$G23*$D23 -> 0 | ... Z24: =+Z23/$G23*$D23 -> 0
A25: 11 | B25: 4118 km pk 1 dan 4128 km pk 10 | C25: Регулировка ширины рельсовой колеи при раздельном скреплении с применением стяжного прибора | D25: 10 | E25: конц/шпал | F25: § 18 | G25: 0.501 | H25: 4 | I25: =+J25*D25/G25 -> 1796.4072 | J25: 90 | K25: 8 | L25: 8 | M25: 8 | N25: 8 | Q25: 8 | R25: 8 | S25: 8 | T25: 8 | U25: 8 | X25: 8 | Y25: 8 | AA25: =SUM(K25:Z25) -> 88 | AB25: =SUM(K25:Z25) -> 88 | AC25: =SUM(K26:Z26) -> 1756.487
K26: =+K25/$G25*$D25 -> 159.68064 | L26: =+L25/$G25*$D25 -> 159.68064 | M26: =+M25/$G25*$D25 -> 159.68064 | N26: =+N25/$G25*$D25 -> 159.68064 | O26: =+O25/$G25*$D25 -> 0 | P26: =+P25/$G25*$D25 -> 0 | Q26: =+Q25/$G25*$D25 -> 159.68064 | R26: =+R25/$G25*$D25 -> 159.68064 | ... Z26: =+Z25/$G25*$D25 -> 0
A27: 12 | C27: Смена железобетонных шпал (одиночная) на щебеночном баласте при раздельном скреплении КБ и скреплении PANDROL FAST CLIP | D27: 1 | E27: шпал | F27: § 11 | G27: 1.83 | H27: 3.6 | I27: =+J27*D27/G27 -> 0 | AA27: =SUM(K27:Z27) -> 0 | AB27: =SUM(K27:Z27) -> 0 | AC27: =SUM(K28:Z28) -> 0
K28: =+K27/$G27*$D27 -> 0 | L28: =+L27/$G27*$D27 -> 0 | M28: =+M27/$G27*$D27 -> 0 | N28: =+N27/$G27*$D27 -> 0 | O28: =+O27/$G27*$D27 -> 0 | P28: =+P27/$G27*$D27 -> 0 | Q28: =+Q27/$G27*$D27 -> 0 | R28: =+R27/$G27*$D27 -> 0 | ... Z28: =+Z27/$G27*$D27 -> 0
A29: 13 | C29: Выправка стрелочного перевода подбивкой брусьев электрошполопобойками ЭШП-9 | D29: 10 | E29: м/брус | F29: § 59 | G29: 1.3 | H29: 5 | I29: =+J29*D29/G29 -> 0 | AA29: =SUM(K29:Z29) -> 0 | AB29: =SUM(K29:Z29) -> 0 | AC29: =SUM(K30:Z30) -> 0
K30: =+K29/$G29*$D29 -> 0 | L30: =+L29/$G29*$D29 -> 0 | M30: =+M29/$G29*$D29 -> 0 | N30: =+N29/$G29*$D29 -> 0 | O30: =+O29/$G29*$D29 -> 0 | P30: =+P29/$G29*$D29 -> 0 | Q30: =+Q29/$G29*$D29 -> 0 | R30: =+R29/$G29*$D29 -> 0 | ... Z30: =+Z29/$G29*$D29 -> 0
A31: 14 | C31: Смена рельсов типов Р65 и Р50 при раздельном скреплении (одиночная) | D31: 1 | E31: рельс | F31: § 21 | G31: 2 | H31: 3.6 | I31: =+J31*D31/G31 -> 0 | AA31: =SUM(K31:Z31) -> 0 | AB31: =SUM(K31:Z31) -> 0 | AC31: =SUM(K32:Z32) -> 0
K32: =+K31/$G31*$D31 -> 0 | L32: =+L31/$G31*$D31 -> 0 | M32: =+M31/$G31*$D31 -> 0 | N32: =+N31/$G31*$D31 -> 0 | O32: =+O31/$G31*$D31 -> 0 | P32: =+P31/$G31*$D31 -> 0 | Q32: =+Q31/$G31*$D31 -> 0 | R32: =+R31/$G31*$D31 -> 0 | ... Z32: =+Z31/$G31*$D31 -> 0
A33: 15 | B33: 4118 km - 4136 km | C33: Обход пути | H33: 3 | J33: 88 | K33: 8 | L33: 8 | M33: 8 | N33: 8 | Q33: 8 | R33: 8 | S33: 8 | T33: 8 | U33: 8 | X33: 8 | Y33: 8 | AA33: =SUM(K33:Z33) -> 88 | AB33: =SUM(K33:Z33) -> 88 | AC33: 0
A34: 16 | C34: Смена рельсов типов Р65 и Р50 при смешанном костыльном скреплении | D34: 1 | E34: рельс | F34: § 22 | G34: 3.69 | H34: 2.8 | I34: =+J34*D34/G34 -> 0 | AA34: =SUM(K34:Z34) -> 0 | AB34: =SUM(K34:Z34) -> 0 | AC34: =SUM(K35:Z35) -> 0
K35: =+K34/$G34*$D34 -> 0 | L35: =+L34/$G34*$D34 -> 0 | M35: =+M34/$G34*$D34 -> 0 | N35: =+N34/$G34*$D34 -> 0 | O35: =+O34/$G34*$D34 -> 0 | P35: =+P34/$G34*$D34 -> 0 | Q35: =+Q34/$G34*$D34 -> 0 | R35: =+R34/$G34*$D34 -> 0 | ... Z35: =+Z34/$G34*$D34 -> 0
C36: жами | I36: =SUM(I5:I35) -> 8761.1807 | J36: =SUM(J5:J35) -> 718 | K36: =+K5+K7+K9+K11+K13+K15+K17+K19+K21+K23+K25+K27+K29+K31+K34+K33 -> 64 | L36: =+L5+L7+L9+L11+L13+L15+L17+L19+L21+L23+L25+L27+L29+L31+L34+L33 -> 64 | M36: =+M5+M7+M9+M11+M13+M15+M17+M19+M21+M23+M25+M27+M29+M31+M34+M33 -> 64 | N36: =+N5+N7+N9+N11+N13+N15+N17+N19+N21+N23+N25+N27+N29+N31+N34+N33 -> 64 | O36: =+O5+O7+O9+O11+O13+O15+O17+O19+O21+O23+O25+O27+O29+O31+O34+O33 -> 0 | P36: =+P5+P7+P9+P11+P13+P15+P17+P19+P21+P23+P25+P27+P29+P31+P34+P33 -> 0 | Q36: =+Q5+Q7+Q9+Q11+Q13+Q15+Q17+Q19+Q21+Q23+Q25+Q27+Q29+Q31+Q34+Q33 -> 64 | R36: =+R5+R7+R9+R11+R13+R15+R17+R19+R21+R23+R25+R27+R29+R31+R34+R33 -> 64 | ... Z36: =+Z5+Z7+Z9+Z11+Z13+Z15+Z17+Z19+Z21+Z23+Z25+Z27+Z29+Z31+Z34+Z33 -> 0 | AA36: =SUM(K36:Z36) -> 704 | AB36: =SUM(AB5:AB35) -> 704 | AC36: =SUM(AC5:AC35) -> 8530.4439
C37: проверит | K37: =+'2-3 бетлар'!C42 -> 64 | L37: =+'2-3 бетлар'!D42 -> 64 | M37: =+'2-3 бетлар'!E42 -> 64 | N37: =+'2-3 бетлар'!F42 -> 64 | O37: =+'2-3 бетлар'!G42 -> 0 | P37: =+'2-3 бетлар'!H42 -> 0 | Q37: =+'2-3 бетлар'!I42 -> 64 | R37: =+'2-3 бетлар'!J42 -> 64 | ... AA37: =+'2-3 бетлар'!S42 -> 704
B39: Задание выдал ПД___________________________________________ | K39: Принял к исполнению ПД_____________________Работы выполнени ПДБ________________________________
D40: (подпись) | R40: (подпись) | AB40: (подпись)
A42: Примечани: 1.Попунктирной линии проводится сплошная черта, определяющая время работ по плану. | K42: Качество выполненных работ
...

Sheet 8- бет
E2: III.Работа механизмов
B3: № | C3: Место работы (км, станция, путь, стрелка) | D3: Наимование механизмов | E3: Количество механизмов | F3: Наимование работ | G3: Единица измерения | I3: Норма на измеритель в чел-час | K3: задание | L3: План и выполнение задания
L5: Числа месяца
L6: 1 | M6: 2 | N6: 3 | O6: 4 | P6: 5 | Q6: 6 | R6: 7 | S6: 8 | T6: 9 | U6: 10 | V6: 11 | W6: 12 | X6: 13 | Y6: 14 | Z6: 15
B7: 1 | D7: АВ-4/ЭШП-9 | F7: Исправление просадок к перекосов пути на щебеночном балласте подбивкой шпал ЭШП-9 | G7: 10 | H7: шпал | I7: & 1 | J7: 1.03 | L7: =+L8/$G$7*$J$7 -> 0 | M7: =+M8/$G$7*$J$7 -> 0 | N7: =+N8/$G$7*$J$7 -> 0 | O7: =+O8/$G$7*$J$7 -> 0 | P7: =+P8/$G$7*$J$7 -> 0 | Q7: =+Q8/$G$7*$J$7 -> 0 | R7: =+R8/$G$7*$J$7 -> 0 | S7: =+S8/$G$7*$J$7 -> 0 | ... Z7: =+Z8/$G$7*$J$7 -> 0 | AB7: =SUM(L7:AA7) -> 0
L8: =+'4-5 бетлар'!K6 -> 0 | M8: =+'4-5 бетлар'!L6 -> 0 | N8: =+'4-5 бетлар'!M6 -> 0 | O8: =+'4-5 бетлар'!N6 -> 0 | P8: =+'4-5 бетлар'!O6 -> 0 | Q8: =+'4-5 бетлар'!P6 -> 0 | R8: =+'4-5 бетлар'!Q6 -> 0 | S8: =+'4-5 бетлар'!R6 -> 0 | ... Z8: =+'4-5 бетлар'!Y6 -> 0 | AB8: =SUM(L8:AA8) -> 0
B9: 2 | D9: АВ-4/ЭШП-9 | F9: Выправка стрелочногоперевода подбивкой брусьев ЭШП-9 | G9: 10 | H9: м/брус | I9: & 59 | J9: 0.884 | L9: =+L10/$G$9*$J$9 -> 0 | M9: =+M10/$G$9*$J$9 -> 0 | N9: =+N10/$G$9*$J$9 -> 0 | O9: =+O10/$G$9*$J$9 -> 0 | P9: =+P10/$G$9*$J$9 -> 0 | Q9: =+Q10/$G$9*$J$9 -> 0 | R9: =+R10/$G$9*$J$9 -> 0 | S9: =+S10/$G$9*$J$9 -> 0 | ... Z9: =+Z10/$G$9*$J$9 -> 0 | AB9: =SUM(L9:AA9) -> 0
L10: =+'4-5 бетлар'!K30 -> 0 | M10: =+'4-5 бетлар'!L30 -> 0 | N10: =+'4-5 бетлар'!M30 -> 0 | O10: =+'4-5 бетлар'!N30 -> 0 | P10: =+'4-5 бетлар'!O30 -> 0 | Q10: =+'4-5 бетлар'!P30 -> 0 | R10: =+'4-5 бетлар'!Q30 -> 0 | S10: =+'4-5 бетлар'!R30 -> 0 | ... Z10: =+'4-5 бетлар'!Y30 -> 0 | AB10: =SUM(L10:AA10) -> 0
A17: 8
C35: Задание выдал ПД _____________________________ | L35: Принял к исполнению ПДБ ___________________________
F36: (подпись) | U36: (подпись)

Sheet 9-бет
E2: III.Работа механизмов
B3: № | C3: Место работы (км, станция, путь, стрелка) | D3: Наимование механизмов | E3: Количество механизмов | F3: Наимование работ | G3: Единица измерения | I3: Норма на измеритель в чел-час | K3: задание | L3: План и выполнение задания
L5: Числа месяца
L6: 16 | M6: 17 | N6: 18 | O6: 19 | P6: 20 | Q6: 21 | R6: 22 | S6: 23 | T6: 24 | U6: 25 | V6: 26 | W6: 27 | X6: 28 | Y6: 29 | Z6: 30 | AA6: 31
B7: 1 | D7: АВ-4/ЭШП-9 | F7: Исправление просадок к перекосов пути на щебеночном балласте подбивкой шпал ЭШП-9 | G7: 10 | H7: шпал | I7: & 1 | J7: 1.03 | L7: =+L8/$G$7*$J$7 -> 0 | M7: =+M8/$G$7*$J$7 -> 0 | N7: =+N8/$G$7*$J$7 -> 0 | O7: =+O8/$G$7*$J$7 -> 0 | P7: =+P8/$G$7*$J$7 -> 0 | Q7: =+Q8/$G$7*$J$7 -> 0 | R7: =+R8/$G$7*$J$7 -> 0 | S7: =+S8/$G$7*$J$7 -> 0 | ... AA7: =+AA8/$G$7*$J$7 -> 0 | AB7: =SUM(L7:AA7) -> 0
L8: =+'6-7 бетлар'!K6 -> 0 | M8: =+'6-7 бетлар'!L6 -> 0 | N8: =+'6-7 бетлар'!M6 -> 0 | O8: =+'6-7 бетлар'!N6 -> 0 | P8: =+'6-7 бетлар'!O6 -> 0 | Q8: =+'6-7 бетлар'!P6 -> 0 | R8: =+'6-7 бетлар'!Q6 -> 0 | S8: =+'6-7 бетлар'!R6 -> 0 | ... AA8: =+'6-7 бетлар'!Z6 -> 0 | AB8: =SUM(L8:AA8) -> 0
B9: 2 | D9: АВ-4/ЭШП-9 | F9: Выправка стрелочногоперевода подбивкой брусьев ЭШП-9 | G9: 10 | H9: м/брус | I9: & 59 | J9: 0.884 | L9: =+L10/$G$9*$J$9 -> 0 | M9: =+M10/$G$9*$J$9 -> 0 | N9: =+N10/$G$9*$J$9 -> 0 | O9: =+O10/$G$9*$J$9 -> 0 | P9: =+P10/$G$9*$J$9 -> 0 | Q9: =+Q10/$G$9*$J$9 -> 0 | R9: =+R10/$G$9*$J$9 -> 0 | S9: =+S10/$G$9*$J$9 -> 0 | ... AA9: =+AA10/$G$9*$J$9 -> 0 | AB9: =SUM(L9:AA9) -> 0
L10: =+'6-7 бетлар'!K30 -> 0 | M10: =+'6-7 бетлар'!L30 -> 0 | N10: =+'6-7 бетлар'!M30 -> 0 | O10: =+'6-7 бетлар'!N30 -> 0 | P10: =+'6-7 бетлар'!O30 -> 0 | Q10: =+'6-7 бетлар'!P30 -> 0 | R10: =+'6-7 бетлар'!Q30 -> 0 | S10: =+'6-7 бетлар'!R30 -> 0 | ... AA10: =+'6-7 бетлар'!Z30 -> 0 | AB10: =SUM(L10:AA10) -> 0
A19: 9
C35: Задание выдал ПД _____________________________ | L35: Принял к исполнению ПДБ ___________________________
F36: (подпись) | U36: (подпись)

Sheet 10-бет
D1: IV. РАБОТА ПУТЕВЫХ ОБХОДЧИКОВ
B2: №п-п | C2: Фамилия путевого обходчика | D2: Обслуживанный участок (№ км. путей) | E2: Место и наимование заданных работ | F2: Срок исполнения | G2: Единица измерения | H2: Задано | I2: Выполнено | J2: Оценка обслуживаемого участка | K2: Причитается премия (сум)
B3: 1 | C3: Nazarov S | D3: 4118 - 4136 | E3: Potenut oslobshix stikovix boltov | F3: 1/ой | G3: штук | H3: 300 | I3: 250 | J3: отлично
B4: 2 | C4: Adambayev A | D4: 4118 - 4136 | E4: Potenut oslobshix stikovix boltov | F4: 1/ой | G4: штук | H4: 300 | I4: 250 | J4: отлично
B5: 3 | C5: Toshpo'latov O | D5: 4118 - 4136 | E5: Potenut oslobshix stikovix boltov | F5: 1/ой | G5: штук | H5: 300 | I5: 250 | J5: отлично
A6: 10 | B6: 4 | C6: Mardinov E | D6: 4118 - 4136 | E6: Potenut oslobshix stikovix boltov | F6: 1/ой | G6: штук | H6: 300 | I6: 250 | J6: отлично
C17: Задание выдал ПД ___________________________________
E18: (подпись)
C19: Работы выполнены ПДБ ____________________________________
D20: (подпись)

Sheet 11-бет
K2: V. ВЕДОМОСТЬ ОБОРОТА МАТЕРИАЛОВ ПО ТЕКУШЕМУ СОДЕРЖАНИЮ ПУТИ
B3: №№ | C3: Наимование материалов с указанием типа | D3: Единица измерения | E3: Годность материала | F3: Снято с пути материалов | W3: Годность материала | X3: Уложено в путь материалов
F4: Число месяца | U4: Итого | X4: Число месяца | AM4: Итого | AO4: В.т.ч
AO5: в глав путь | AP5: станц путь | AQ5: перевод на стрел
F6: 1 | G6: 2 | H6: 3 | I6: 4 | J6: 5 | K6: 6 | L6: 7 | M6: 8 | N6: 9 | O6: 10 | P6: 11 | Q6: 12 | R6: 13 | S6: 14 | T6: 15 | X6: 1 | Y6: 2 | Z6: 3 | AA6: 4 | AB6: 5 | AC6: 6 | AD6: 7 | AE6: 8 | AF6: 9 | AG6: 10 | AH6: 11 | AI6: 12 | AJ6: 13 | AK6: 14 | AL6: 15
B7: 1 | C7: Изолятсия Р-65 новая | D7: туп | E7: годн | U7: =SUM(F7:T7) -> 0 | W7: нов | AM7: =SUM(X7:AL7) -> 0 | AO7: =+AM7 -> 0
E8: негод | U8: =SUM(F8:T8) -> 0 | W8: старо | AM8: =SUM(X8:AL8) -> 0 | AO8: =+AM8 -> 0
B9: 2 | E9: годн | U9: =SUM(F9:T9) -> 0 | W9: нов | AM9: =SUM(X9:AL9) -> 0 | AO9: =+AM9 -> 0
E10: негод | U10: =SUM(F10:T10) -> 0 | W10: старо | AM10: =SUM(X10:AL10) -> 0 | AO10: =+AM10 -> 0
E11: годн | U11: =SUM(F11:T11) -> 0 | W11: нов | AM11: =SUM(X11:AL11) -> 0 | AO11: =+AM11 -> 0
E12: негод | U12: =SUM(F12:T12) -> 0 | W12: старо | AM12: =SUM(X12:AL12) -> 0 | AO12: =+AM12 -> 0
E13: годн | U13: =SUM(F13:T13) -> 0 | W13: нов | AM13: =SUM(X13:AL13) -> 0 | AO13: =+AM13 -> 0
E14: негод | U14: =SUM(F14:T14) -> 0 | W14: старо | AM14: =SUM(X14:AL14) -> 0 | AO14: =+AM14 -> 0
E15: годн | U15: =SUM(F15:T15) -> 0 | W15: нов | AM15: =SUM(X15:AL15) -> 0 | AO15: =+AM15 -> 0
A16: 11 | E16: негод | U16: =SUM(F16:T16) -> 0 | W16: старо | AM16: =SUM(X16:AL16) -> 0 | AO16: =+AM16 -> 0
E17: годн | U17: =SUM(F17:T17) -> 0 | W17: нов | AM17: =SUM(X17:AL17) -> 0 | AO17: =+AM17 -> 0
E18: негод | U18: =SUM(F18:T18) -> 0 | W18: старо | AM18: =SUM(X18:AL18) -> 0 | AO18: =+AM18 -> 0
E19: годн | U19: =SUM(F19:T19) -> 0 | W19: нов | AM19: =SUM(X19:AL19) -> 0 | AO19: =+AM19 -> 0
E20: негод | U20: =SUM(F20:T20) -> 0 | W20: старо | AM20: =SUM(X20:AL20) -> 0 | AO20: =+AM20 -> 0
E21: годн | U21: =SUM(F21:T21) -> 0 | W21: нов | AM21: =SUM(X21:AL21) -> 0 | AO21: =+AM21 -> 0
E22: негод | U22: =SUM(F22:T22) -> 0 | W22: старо | AM22: =SUM(X22:AL22) -> 0 | AO22: =+AM22 -> 0
E23: годн | U23: =SUM(F23:T23) -> 0 | W23: нов | AM23: =SUM(X23:AL23) -> 0 | AO23: =+AM23 -> 0
E24: негод | U24: =SUM(F24:T24) -> 0 | W24: старо | AM24: =SUM(X24:AL24) -> 0 | AO24: =+AM24 -> 0
E25: годн | U25: =SUM(F25:T25) -> 0 | W25: нов | AM25: =SUM(X25:AL25) -> 0 | AO25: =+AM25 -> 0
E26: негод | U26: =SUM(F26:T26) -> 0 | W26: старо | AM26: =SUM(X26:AL26) -> 0 | AO26: =+AM26 -> 0
E27: годн | U27: =SUM(F27:T27) -> 0 | W27: нов | AM27: =SUM(X27:AL27) -> 0 | AO27: =+AM27 -> 0
E28: негод | U28: =SUM(F28:T28) -> 0 | W28: старо | AM28: =SUM(X28:AL28) -> 0 | AO28: =+AM28 -> 0
... E30: негод | U30: =SUM(F30:T30) -> 0 | W30: старо | AM30: =SUM(X30:AL30) -> 0 | AO30: =+AM30 -> 0
E33: Составил ПД____________________________________________ | Y33: Проверил ПДБ ________________________________________________________
I34: (подпись) | AD34: (подпись)

Sheet 12-бет
J2: V. ВЕДОМОСТЬ ОБОРОТА МАТЕРИАЛОВ ПО ТЕКУШЕМУ СОДЕРЖАНИЮ ПУТИ
B3: №№ | C3: Наимование материалов с указанием типа | D3: Единица измерения | E3: Годность материала | F3: Снято с пути материалов | X3: Годность материала | Y3: Уложено в путь материалов
F4: Число месяца | V4: Итого | Y4: Число месяца | AO4: Итого | AQ4: В.т.ч
AQ5: в глав путь | AR5: станц путь | AS5: перевод на стрел
F6: 16 | G6: 17 | H6: 18 | I6: 19 | J6: 20 | K6: 21 | L6: 22 | M6: 23 | N6: 24 | O6: 25 | P6: 26 | Q6: 27 | R6: 28 | S6: 29 | T6: 30 | U6: 31 | Y6: 16 | Z6: 17 | AA6: 18 | AB6: 19 | AC6: 20 | AD6: 21 | AE6: 22 | AF6: 23 | AG6: 24 | AH6: 25 | AI6: 26 | AJ6: 27 | AK6: 28 | AL6: 29 | AM6: 30 | AN6: 31
B7: 1 | C7: Изолятсия Р-65 новая | D7: туп | E7: годн | V7: =SUM(F7:U7) -> 0 | X7: нов | AO7: =SUM(Y7:AN7) -> 0 | AQ7: =+AO7 -> 0
E8: негод | V8: =SUM(F8:U8) -> 0 | X8: старо | AO8: =SUM(Y8:AN8) -> 0 | AQ8: =+AO8 -> 0
B9: 2 | E9: годн | V9: =SUM(F9:U9) -> 0 | X9: нов | AO9: =SUM(Y9:AN9) -> 0 | AQ9: =+AO9 -> 0
E10: негод | V10: =SUM(F10:U10) -> 0 | X10: старо | AO10: =SUM(Y10:AN10) -> 0 | AQ10: =+AO10 -> 0
E11: годн | V11: =SUM(F11:U11) -> 0 | X11: нов | AO11: =SUM(Y11:AN11) -> 0 | AQ11: =+AO11 -> 0
E12: негод | V12: =SUM(F12:U12) -> 0 | X12: старо | AO12: =SUM(Y12:AN12) -> 0 | AQ12: =+AO12 -> 0
E13: годн | V13: =SUM(F13:U13) -> 0 | X13: нов | AO13: =SUM(Y13:AN13) -> 0 | AQ13: =+AO13 -> 0
E14: негод | V14: =SUM(F14:U14) -> 0 | X14: старо | AO14: =SUM(Y14:AN14) -> 0 | AQ14: =+AO14 -> 0
E15: годн | V15: =SUM(F15:U15) -> 0 | X15: нов | AO15: =SUM(Y15:AN15) -> 0 | AQ15: =+AO15 -> 0
A16: 12 | E16: негод | V16: =SUM(F16:U16) -> 0 | X16: старо | AO16: =SUM(Y16:AN16) -> 0 | AQ16: =+AO16 -> 0
E17: годн | V17: =SUM(F17:U17) -> 0 | X17: нов | AO17: =SUM(Y17:AN17) -> 0 | AQ17: =+AO17 -> 0
E18: негод | V18: =SUM(F18:U18) -> 0 | X18: старо | AO18: =SUM(Y18:AN18) -> 0 | AQ18: =+AO18 -> 0
E19: годн | V19: =SUM(F19:U19) -> 0 | X19: нов | AO19: =SUM(Y19:AN19) -> 0 | AQ19: =+AO19 -> 0
E20: негод | V20: =SUM(F20:U20) -> 0 | X20: старо | AO20: =SUM(Y20:AN20) -> 0 | AQ20: =+AO20 -> 0
E21: годн | V21: =SUM(F21:U21) -> 0 | X21: нов | AO21: =SUM(Y21:AN21) -> 0 | AQ21: =+AO21 -> 0
E22: негод | V22: =SUM(F22:U22) -> 0 | X22: старо | AO22: =SUM(Y22:AN22) -> 0 | AQ22: =+AO22 -> 0
E23: годн | V23: =SUM(F23:U23) -> 0 | X23: нов | AO23: =SUM(Y23:AN23) -> 0 | AQ23: =+AO23 -> 0
E24: негод | V24: =SUM(F24:U24) -> 0 | X24: старо | AO24: =SUM(Y24:AN24) -> 0 | AQ24: =+AO24 -> 0
E25: годн | V25: =SUM(F25:U25) -> 0 | X25: нов | AO25: =SUM(Y25:AN25) -> 0 | AQ25: =+AO25 -> 0
E26: негод | V26: =SUM(F26:U26) -> 0 | X26: старо | AO26: =SUM(Y26:AN26) -> 0 | AQ26: =+AO26 -> 0
E27: годн | V27: =SUM(F27:U27) -> 0 | X27: нов | AO27: =SUM(Y27:AN27) -> 0 | AQ27: =+AO27 -> 0
E28: негод | V28: =SUM(F28:U28) -> 0 | X28: старо | AO28: =SUM(Y28:AN28) -> 0 | AQ28: =+AO28 -> 0
... E30: негод | V30: =SUM(F30:U30) -> 0 | X30: старо | AO30: =SUM(Y30:AN30) -> 0 | AQ30: =+AO30 -> 0
E33: Составил ПД____________________________________________ | Z33: Проверил ПДБ ________________________________________________________
I34: (подпись) | AE34: (подпись)

Sheet 13-бет
C1: VI.СОСТОЯНИЕ И ОЦЕНКА ПУТИ И ПУТЕВЫХ УСТРОЙСТВ
C2: Перегон__________________________________________ СТАНЦИЯ__________________________________________
B3: № | C3: ПОКАЗАТЕЛИ | D3: Измеритель | E3: № километров главного пути или приемо - отправочных и прочих путей
E4: 4118 | F4: 4119 | G4: 4120 | H4: 4121 | I4: 4122 | J4: 4123 | K4: 4124 | L4: 4125 | M4: 4126 | N4: 4127 | O4: 4128
B5: 1 | C5: Состояние пути по показаниям путеизмерителбного вагона или путеизмерительной тележки за преыдуший месяц | D5: балл
B6: 2 | C6: Задания на отчетных месяц | D6: балл
B7: 3 | C7: Состояние пути по показаниям путеизмерителбного вагона или путеизмерительной тележки за преыдуший месяц | D7: балл
B8: 4 | C8: Наличие несменных остродефектных рельсов | D8: шт
B9: 5 | C9: Наличие кустов из 3-х и более подряд негодных шпал | D9: куст
B10: 6 | C10: Протяжение пути, требующего разгонки зазоров и закрепления от угона | D10: п. м.
B11: 7 | C11: Протяжение водоотводных устройств, требущих очистки | D11: п. м.
A12: 13 | B12: 8 | C12: Общая оценка состояния пути и путевых устройств | D12: оценка
C13: Перегон__________________________________________Станция__________________________________________
B15: № | C15: ПОКАЗАТЕЛИ | D15: Измеритель | E15: № километров главного пути или приемо - отправочных и прочих путей
B17: 1 | C17: Состояние пути по показаниям путеизмерителбного вагона или путеизмерительной тележки за преыдуший месяц | D17: балл
B18: 2 | C18: Задания на отчетных месяц | D18: балл
B19: 3 | C19: Состояние пути по показаниям путеизмерителбного вагона или путеизмерительной тележки за преыдуший месяц | D19: балл
B20: 4 | C20: Наличие несменных остродефектных рельсов | D20: шт
B21: 5 | C21: Наличие кустов из 3-х и более подряд негодных шпал | D21: куст
B22: 6 | C22: Протяжение пути, требующего разгонки зазоров и закрепления от угона | D22: п. м.
B23: 7 | C23: Протяжение водоотводных устройств, требущих очистки | D23: п. м.
B24: 8 | C24: Общая оценка состояния пути и путевых устройств | D24: оценка
C25: Перегон__________________________________________Станция__________________________________________

Sheet 14-бет
C1: VI.СОСТОЯНИЕ И ОЦЕНКА ПУТИ И ПУТЕВЫХ УСТРОЙСТВ
C2: Перегон__________________________________________ СТАНЦИЯ__________________________________________
B3: № | C3: ПОКАЗАТЕЛИ | D3: Измеритель | E3: № километров главного пути или приемо - отправочных и прочих путей
B5: 1 | C5: Состояние пути по показаниям путеизмерителбного вагона или путеизмерительной тележки за преыдуший месяц | D5: балл
B6: 2 | C6: Задания на отчетных месяц | D6: балл
B7: 3 | C7: Состояние пути по показаниям путеизмерителбного вагона или путеизмерительной тележки за преыдуший месяц | D7: балл
B8: 4 | C8: Наличие несменных остродефектных рельсов | D8: шт
B9: 5 | C9: Наличие кустов из 3-х и более подряд негодных шпал | D9: куст
B10: 6 | C10: Протяжение пути, требующего разгонки зазоров и закрепления от угона | D10: п. м.
B11: 7 | C11: Протяжение водоотводных устройств, требущих очистки | D11: п. м.
A12: 14 | B12: 8 | C12: Общая оценка состояния пути и путевых устройств | D12: оценка
C13: Перегон__________________________________________Станция__________________________________________
B15: № | C15: ПОКАЗАТЕЛИ | D15: Измеритель | E15: № километров главного пути или приемо - отправочных и прочих путей
B17: 1 | C17: Состояние пути по показаниям путеизмерителбного вагона или путеизмерительной тележки за преыдуший месяц | D17: балл
B18: 2 | C18: Задания на отчетных месяц | D18: балл
B19: 3 | C19: Состояние пути по показаниям путеизмерителбного вагона или путеизмерительной тележки за преыдуший месяц | D19: балл
B20: 4 | C20: Наличие несменных остродефектных рельсов | D20: шт
B21: 5 | C21: Наличие кустов из 3-х и более подряд негодных шпал | D21: куст
B22: 6 | C22: Протяжение пути, требующего разгонки зазоров и закрепления от угона | D22: п. м.
B23: 7 | C23: Протяжение водоотводных устройств, требущих очистки | D23: п. м.
B24: 8 | C24: Общая оценка состояния пути и путевых устройств | D24: оценка
C25: Перегон__________________________________________Станция__________________________________________
